Workbook

Sheet PDI
A1: Nome | B1: Email | C1: Cpf | D1: Times | E1: Tags Privadas | F1: Tags Públicas | G1: Área | H1: Identificador | I1: status | J1: Líder | K1: Aprovado pelo líder? | L1: Total de Áreas de desenvolvimento | M1: Atualizado em (yyyy-mm-dd) | N1: Não iniciada | O1: Em progresso | P1: Finalizada | Q1: Engajamento | R1: PDI Finalizado? | S1: Progresso | T1: Macroáreas Desenvolvidas | U1: Macroáreas com Ações Pendentes
A2: Adelice Thomaz Soares Novak | B2: adelice@to.sebrae.com.br | D2: UAC-UNIDADE DE ARTICULAÇÃO E COMPETITIVIDADE | I2: Ativo | J2: Bruno Martins Vieira | K2: Sim | L2: 8 | M2: 2025-09-12 | N2: 0 | O2: 0 | P2: 8 | Q2: 4 | R2: =IF(OR(L2="",L2=0)," ",IF(P2=L2,"Terminou","Não terminou")) -> Terminou | S2: =IFERROR(P2/L2,0) -> 1 | T2: =IFERROR(VLOOKUP(TRIM($A2),'Ações Finalizadas'!$A:$O,15,FALSE),"") -> Comunicação, Ética, Integridade e Responsabilidade, Liderança e Gestão de Pessoas, Relacionamento, Planejamento, Foco e Resultados, Gestão de Equipes, Tecnologia, Dados e Transformação Digital | U2: =IFERROR(VLOOKUP(TRIM($A2),'Ações Não Finalizadas'!$A:$G,15,FALSE),"")
A3: Ademir Whitman Gomes Rego | B3: ademir@to.sebrae.com.br | D3: Regional Vale do Araguaia | I3: Ativo | J3: Renata Moura Alves Simas | K3: Sim | L3: 11 | M3: 2025-08-19 | N3: 11 | O3: 0 | P3: 0 | Q3: 2 | R3: =IF(OR(L3="",L3=0)," ",IF(P3=L3,"Terminou","Não terminou")) -> Não terminou | S3: =IFERROR(P3/L3,0) -> 0 | T3: =IFERROR(VLOOKUP(TRIM($A3),'Ações Finalizadas'!$A:$O,15,FALSE),"") | U3: =IFERROR(VLOOKUP(TRIM($A3),'Ações Não Finalizadas'!$A:$G,15,FALSE),"")
A4: Admary Monteiro Barbosa | B4: admary.monteiro@to.sebrae.com.br | D4: Regional Portal do Jalapao | I4: Ativo | J4: Millena Pereira Lima Rodrigues | K4: Sim | L4: 9 | M4: 2025-12-19 | N4: 0 | O4: 0 | P4: 9 | Q4: 4 | R4: =IF(OR(L4="",L4=0)," ",IF(P4=L4,"Terminou","Não terminou")) -> Terminou | S4: =IFERROR(P4/L4,0) -> 1 | T4: =IFERROR(VLOOKUP(TRIM($A4),'Ações Finalizadas'!$A:$O,15,FALSE),"") -> Atendimento e Relacionamento com o Cliente, Estratégia e Indicadores, Ética, Integridade e Responsabilidade, Gestão de Projetos e Processos, Liderança e Gestão de Pessoas, Planejamento, Foco e Resultados, Vendas, Negociação e Soluções Comerciais, Comunicação | U4: =IFERROR(VLOOKUP(TRIM($A4),'Ações Não Finalizadas'!$A:$G,15,FALSE),"")
A5: Adrielle Andrade | B5: adrielle.andrade@to.sebrae.com.br | D5: Regional Sul | I5: Ativo | J5: Paula dos Reis Coelho Alencar Sousa | K5: Sim | L5: 2 | M5: 2025-12-19 | N5: 0 | O5: 0 | P5: 2 | Q5: 3 | R5: =IF(OR(L5="",L5=0)," ",IF(P5=L5,"Terminou","Não terminou")) -> Terminou | S5: =IFERROR(P5/L5,0) -> 1 | T5: =IFERROR(VLOOKUP(TRIM($A5),'Ações Finalizadas'!$A:$O,15,FALSE),"") -> Desenvolvimento Programa Integração | U5: =IFERROR(VLOOKUP(TRIM($A5),'Ações Não Finalizadas'!$A:$G,15,FALSE),"")
A6: Aldeni Batista Torres | B6: aldeni.torres@to.sebrae.com.br | D6: Regional Médio Norte Colinas | I6: Ativo | J6: Aldeni Batista Torres | K6: Sim | L6: 7 | M6: 2025-12-18 | N6: 0 | O6: 1 | P6: 6 | Q6: 4 | R6: =IF(OR(L6="",L6=0)," ",IF(P6=L6,"Terminou","Não terminou")) -> Não terminou | S6: =(P6 + 0.5*O6) / L6 -> 0.92857143 | T6: =IFERROR(VLOOKUP(TRIM($A6),'Ações Finalizadas'!$A:$O,15,FALSE),"") -> Atendimento e Relacionamento com o Cliente, Inteligência Emocional e Autoconhecimento, Gestão de Projetos e Processos, Protagonismo, Autogestão e Tomada de Decisão, Gestão de Equipes | U6: =IFERROR(VLOOKUP(TRIM($A6),'Ações Não Finalizadas'!$A:$G,15,FALSE),"")
A7: Alencar Hubner Borelli | B7: alencar.borelli@to.sebrae.com.br | D7: UAS-UNIDADE DE ADMINISTRAÇÃO E SUPRIMENTOS | I7: Ativo | J7: Ana Paula Alves Santos | K7: Sim | L7: 2 | M7: 2025-12-09 | N7: 0 | O7: 0 | P7: 2 | Q7: 3 | R7: =IF(OR(L7="",L7=0)," ",IF(P7=L7,"Terminou","Não terminou")) -> Terminou | S7: =IFERROR(P7/L7,0) -> 1 | T7: =IFERROR(VLOOKUP(TRIM($A7),'Ações Finalizadas'!$A:$O,15,FALSE),"") -> Desenvolvimento de Ferramentas de Apoio na Execução, Ética, Integridade e Responsabilidade | U7: =IFERROR(VLOOKUP(TRIM($A7),'Ações Não Finalizadas'!$A:$G,15,FALSE),"")
A8: Alex Veras Dias | B8: alex.dias@to.sebrae.com.br | D8: URI-UNIDADE DE RELACIONAMENTO INSTITUCIONAL | I8: Ativo | J8: Gilzane Pereira Amaral | K8: Sim | L8: 9 | M8: 2025-12-19 | N8: 0 | O8: 0 | P8: 9 | Q8: 4 | R8: =IF(OR(L8="",L8=0)," ",IF(P8=L8,"Terminou","Não terminou")) -> Terminou | S8: =IFERROR(P8/L8,0) -> 1 | T8: =IFERROR(VLOOKUP(TRIM($A8),'Ações Finalizadas'!$A:$O,15,FALSE),"") -> Comunicação, Estratégia e Indicadores, Ética, Integridade e Responsabilidade, Finanças, Orçamento e Contabilidade Pública, Gestão de Tempo, Liderança e Gestão de Pessoas, Planejamento, Foco e Resultados, Políticas Públicas e Desenvolvimento Territorial | U8: =IFERROR(VLOOKUP(TRIM($A8),'Ações Não Finalizadas'!$A:$G,15,FALSE),"")
A9: Alice Sousa Santos Costa | B9: alice.costa@to.sebrae.com.br | D9: Regional Sul | I9: Ativo | J9: Paula dos Reis Coelho Alencar Sousa | K9: Sim | L9: 7 | M9: 2025-12-01 | N9: 0 | O9: 0 | P9: 7 | Q9: 4 | R9: =IF(OR(L9="",L9=0)," ",IF(P9=L9,"Terminou","Não terminou")) -> Terminou | S9: =IFERROR(P9/L9,0) -> 1 | T9: =IFERROR(VLOOKUP(TRIM($A9),'Ações Finalizadas'!$A:$O,15,FALSE),"") -> Atitude Inovadora com Visão de Futuro, Estratégia e Indicadores, Gestão do Conhecimento e Documentação Institucional, Inteligência Emocional e Autoconhecimento, Planejamento, Foco e Resultados, Vendas, Negociação e Soluções Comerciais, Comunicação | U9: =IFERROR(VLOOKUP(TRIM($A9),'Ações Não Finalizadas'!$A:$G,15,FALSE),"")
A10: Aline Almeida | B10: aline.almeida@to.sebrae.com.br | D10: Regional Médio Norte Colinas | I10: Ativo | J10: Aldeni Batista Torres | K10: Sim | L10: 2 | M10: 2025-12-15 | N10: 0 | O10: 0 | P10: 2 | Q10: 3 | R10: =IF(OR(L10="",L10=0)," ",IF(P10=L10,"Terminou","Não terminou")) -> Terminou | S10: =IFERROR(P10/L10,0) -> 1 | T10: =IFERROR(VLOOKUP(TRIM($A10),'Ações Finalizadas'!$A:$O,15,FALSE),"") -> Desenvolvimento Programa Integração | U10: =IFERROR(VLOOKUP(TRIM($A10),'Ações Não Finalizadas'!$A:$G,15,FALSE),"")
A11: Alorran de Freitas Barbosa | B11: alorran.barbosa@to.sebrae.com.br | D11: UTIC-UNIDADE DE TECNOLOGIA DA INFORM. E COMUNICAÇÃO DE DADOS | I11: Ativo | J11: Leonardo Campelo Leite Guedes | K11: Sim | L11: 8 | M11: 2025-12-19 | N11: 3 | O11: 0 | P11: 7 | Q11: 4 | R11: =IF(OR(L11="",L11=0)," ",IF(P11=L11,"Terminou","Não terminou")) -> Não terminou | S11: =IFERROR(P11/L11,0) -> 0.875 | T11: =IFERROR(VLOOKUP(TRIM($A11),'Ações Finalizadas'!$A:$O,15,FALSE),"") -> Competências Técnicas da Área, Ética, Integridade e Responsabilidade, Gestão de Tempo, Inteligência Emocional e Autoconhecimento, Planejamento, Foco e Resultados, Comunicação | U11: =IFERROR(VLOOKUP(TRIM($A11),'Ações Não Finalizadas'!$A:$G,15,FALSE),"")
A12: Amaggeldo Barbosa | B12: amaggeldo@to.sebrae.com.br | D12: Regional Metropolitana | I12: Ativo | J12: Amaggeldo Barbosa | K12: Sim | L12: 6 | M12: 2025-12-11 | N12: 0 | O12: 0 | P12: 6 | Q12: 4 | R12: =IF(OR(L12="",L12=0)," ",IF(P12=L12,"Terminou","Não terminou")) -> Terminou | S12: =IFERROR(P12/L12,0) -> 1 | T12: =IFERROR(VLOOKUP(TRIM($A12),'Ações Finalizadas'!$A:$O,15,FALSE),"") -> Ética, Integridade e Responsabilidade, Atitude Inovadora com Visão de Futuro, Estratégia e Indicadores, Tecnologia, Dados e Transformação Digital, Comunicação | U12: =IFERROR(VLOOKUP(TRIM($A12),'Ações Não Finalizadas'!$A:$G,15,FALSE),"")
A13: Amanda Soares Santos | B13: amanda.santos@to.sebrae.com.br | D13: UGOC-UNIDADE DE GESTÃO ORÇ. CONTABILIDADE E FINANÇAS | I13: Ativo | J13: Andreia Rodrigues Facundes | K13: Sim | L13: 11 | M13: 2025-12-19 | N13: 0 | O13: 0 | P13: 11 | Q13: 4 | R13: =IF(OR(L13="",L13=0)," ",IF(P13=L13,"Terminou","Não terminou")) -> Terminou | S13: =IFERROR(P13/L13,0) -> 1 | T13: =IFERROR(VLOOKUP(TRIM($A13),'Ações Finalizadas'!$A:$O,15,FALSE),"") -> Estratégia e Indicadores, Ética, Integridade e Responsabilidade, Gestão de Tempo, Gestão do Conhecimento e Documentação Institucional, Inovação, Criatividade e Visão Estratégica, Inteligência Emocional e Autoconhecimento, Planejamento, Foco e Resultados, Protagonismo, Autogestão e Tomada de Decisão, Comunicação | U13: =IFERROR(VLOOKUP(TRIM($A13),'Ações Não Finalizadas'!$A:$G,15,FALSE),"")
A14: Ana Cassia de Oliveira Costa | B14: ana.costa@to.sebrae.com.br | D14: UMC-UNIDADE DE MARKETING E COMUNICAÇÃO | I14: Ativo | J14: Nemias Gomes | K14: Sim | L14: 8 | M14: 2025-12-19 | N14: 0 | O14: 0 | P14: 8 | Q14: 4 | R14: =IF(OR(L14="",L14=0)," ",IF(P14=L14,"Terminou","Não terminou")) -> Terminou | S14: =IFERROR(P14/L14,0) -> 1 | T14: =IFERROR(VLOOKUP(TRIM($A14),'Ações Finalizadas'!$A:$O,15,FALSE),"") -> Atitude Inovadora com Visão de Futuro, Ética, Integridade e Responsabilidade, Gestão de Projetos e Processos, Gestão de Tempo, Planejamento, Foco e Resultados, Protagonismo, Autogestão e Tomada de Decisão, Comunicação | U14: =IFERROR(VLOOKUP(TRIM($A14),'Ações Não Finalizadas'!$A:$G,15,FALSE),"")
A15: Ana Estela Goetten | B15: ana.goetten@to.sebrae.com.br | D15: Regional Metropolitana | I15: Ativo | J15: Amaggeldo Barbosa | K15: Sim | L15: 3 | M15: 2025-12-03 | N15: 0 | O15: 0 | P15: 3 | Q15: 4 | R15: =IF(OR(L15="",L15=0)," ",IF(P15=L15,"Terminou","Não terminou")) -> Terminou | S15: =IFERROR(P15/L15,0) -> 1 | T15: =IFERROR(VLOOKUP(TRIM($A15),'Ações Finalizadas'!$A:$O,15,FALSE),"") -> Desenvolvimento Programa Integração | U15: =IFERROR(VLOOKUP(TRIM($A15),'Ações Não Finalizadas'!$A:$G,15,FALSE),"")
A16: Ana Flávia Mendes Borges | B16: ana.borges@to.sebrae.com.br | D16: UAC-UNIDADE DE ARTICULAÇÃO E COMPETITIVIDADE | I16: Ativo | J16: Bruno Martins Vieira | K16: Sim | L16: 5 | M16: 2025-09-23 | N16: 0 | O16: 0 | P16: 5 | Q16: 4 | R16: =IF(OR(L16="",L16=0)," ",IF(P16=L16,"Terminou","Não terminou")) -> Terminou | S16: =IFERROR(P16/L16,0) -> 1 | T16: =IFERROR(VLOOKUP(TRIM($A16),'Ações Finalizadas'!$A:$O,15,FALSE),"") -> Atitude Inovadora com Visão de Futuro, Ética, Integridade e Responsabilidade, Gestão de Tempo, Comunicação | U16: =IFERROR(VLOOKUP(TRIM($A16),'Ações Não Finalizadas'!$A:$G,15,FALSE),"")
A17: Ana Maria Leal Cunha de Freitas | B17: ana.freitas@to.sebrae.com.br | D17: Regional Médio Norte Colinas | I17: Ativo | J17: Aldeni Batista Torres | K17: Sim | L17: 13 | M17: 2025-12-17 | N17: 0 | O17: 0 | P17: 13 | Q17: 4 | R17: =IF(OR(L17="",L17=0)," ",IF(P17=L17,"Terminou","Não terminou")) -> Terminou | S17: =IFERROR(P17/L17,0) -> 1 | T17: =IFERROR(VLOOKUP(TRIM($A17),'Ações Finalizadas'!$A:$O,15,FALSE),"") -> Ética, Integridade e Responsabilidade, Atitude Inovadora com Visão de Futuro, Finanças, Orçamento e Contabilidade Pública, Gestão de Projetos e Processos, Gestão de Tempo, Protagonismo, Autogestão e Tomada de Decisão, Vendas, Negociação e Soluções Comerciais, Competências Técnicas da Área, Comunicação, Desenvolvimento Programa Integração | U17: =IFERROR(VLOOKUP(TRIM($A17),'Ações Não Finalizadas'!$A:$G,15,FALSE),"")
A18: Ana Paula Alves de Lima Rocha | B18: anapaula.lima@to.sebrae.com.br | D18: UTIC-UNIDADE DE TECNOLOGIA DA INFORM. E COMUNICAÇÃO DE DADOS | I18: Ativo | J18: Leonardo Campelo Leite Guedes | K18: Sim | L18: 1 | M18: 2025-12-03 | N18: 1 | O18: 0 | P18: 1 | Q18: 2 | R18: =IF(OR(L18="",L18=0)," ",IF(P18=L18,"Terminou","Não terminou")) -> Terminou | S18: =IFERROR(P18/L18,0) -> 1 | T18: =IFERROR(VLOOKUP(TRIM($A18),'Ações Finalizadas'!$A:$O,15,FALSE),"") -> Inteligência Emocional e Autoconhecimento | U18: =IFERROR(VLOOKUP(TRIM($A18),'Ações Não Finalizadas'!$A:$G,15,FALSE),"")
A19: Ana Paula Alves Santos | B19: paula.alves@to.sebrae.com.br | D19: UAS-UNIDADE DE ADMINISTRAÇÃO E SUPRIMENTOS | H19: ANA PAULA ALVES SANTOS | I19: Ativo | J19: Ana Paula Alves Santos | K19: Sim | L19: 4 | M19: 2025-12-11 | N19: 0 | O19: 0 | P19: 4 | Q19: 4 | R19: =IF(OR(L19="",L19=0)," ",IF(P19=L19,"Terminou","Não terminou")) -> Terminou | S19: =IFERROR(P19/L19,0) -> 1 | T19: =IFERROR(VLOOKUP(TRIM($A19),'Ações Finalizadas'!$A:$O,15,FALSE),"") -> Ética, Integridade e Responsabilidade, Gestão de Equipes, Inovação, Criatividade e Visão Estratégica, Inteligência Emocional e Autoconhecimento | U19: =IFERROR(VLOOKUP(TRIM($A19),'Ações Não Finalizadas'!$A:$G,15,FALSE),"")
A20: Ana Paula Carvalho Desconsi | B20: anapaula.desconsi@to.sebrae.com.br | D20: Regional Bico do Papagaio | I20: Ativo | J20: Edvaldo Pereira Lima Júnior | K20: Sim | L20: 3 | M20: 2025-12-19 | N20: 0 | O20: 0 | P20: 3 | Q20: 4 | R20: =IF(OR(L20="",L20=0)," ",IF(P20=L20,"Terminou","Não terminou")) -> Terminou | S20: =IFERROR(P20/L20,0) -> 1 | T20: =IFERROR(VLOOKUP(TRIM($A20),'Ações Finalizadas'!$A:$O,15,FALSE),"") -> Protagonismo, Autogestão e Tomada de Decisão, Desenvolvimento Programa Integração | U20: =IFERROR(VLOOKUP(TRIM($A20),'Ações Não Finalizadas'!$A:$G,15,FALSE),"")
A21: Ana Paula Cunha Soares | B21: paula.soares@to.sebrae.com.br | D21: UAS-UNIDADE DE ADMINISTRAÇÃO E SUPRIMENTOS | I21: Ativo | J21: Ana Paula Alves Santos | K21: Sim | L21: 10 | M21: 2025-12-04 | N21: 0 | O21: 0 | P21: 10 | Q21: 4 | R21: =IF(OR(L21="",L21=0)," ",IF(P21=L21,"Terminou","Não terminou")) -> Terminou | S21: =IFERROR(P21/L21,0) -> 1 | T21: =IFERROR(VLOOKUP(TRIM($A21),'Ações Finalizadas'!$A:$O,15,FALSE),"") -> Ética, Integridade e Responsabilidade, Atendimento e Relacionamento com o Cliente, Compras, Facilities e Gestão Contratual, Estratégia e Indicadores, Gestão de Tempo, Inteligência Emocional e Autoconhecimento, Planejamento, Foco e Resultados, Presença Executiva, Comunicação | U21: =IFERROR(VLOOKUP(TRIM($A21),'Ações Não Finalizadas'!$A:$G,15,FALSE),"")
A22: Andre Silva Gomes | B22: andre.gomes@to.sebrae.com.br | D22: Regional Portal do Jalapao | I22: Ativo | J22: Millena Pereira Lima Rodrigues | K22: Sim | L22: 11 | M22: 2025-12-19 | N22: 0 | O22: 0 | P22: 11 | Q22: 4 | R22: =IF(OR(L22="",L22=0)," ",IF(P22=L22,"Terminou","Não terminou")) -> Terminou | S22: =IFERROR(P22/L22,0) -> 1 | T22: =IFERROR(VLOOKUP(TRIM($A22),'Ações Finalizadas'!$A:$O,15,FALSE),"") -> Estratégia e Indicadores, Ética, Integridade e Responsabilidade, Gestão do Conhecimento e Documentação Institucional, Inteligência Emocional e Autoconhecimento, Liderança e Gestão de Pessoas, Planejamento, Foco e Resultados, Vendas, Negociação e Soluções Comerciais, Comunicação | U22: =IFERROR(VLOOKUP(TRIM($A22),'Ações Não Finalizadas'!$A:$G,15,FALSE),"")
A23: Andreia Rodrigues Facundes | B23: andreia.facundes@to.sebrae.com.br | D23: UGOC-UNIDADE DE GESTÃO ORÇ. CONTABILIDADE E FINANÇAS | I23: Ativo | J23: Andreia Rodrigues Facundes | K23: Sim | L23: 4 | M23: 2025-12-09 | N23: 4 | O23: 0 | P23: 0 | Q23: 2 | R23: =IF(OR(L23="",L23=0)," ",IF(P23=L23,"Terminou","Não terminou")) -> Não terminou | S23: =IFERROR(P23/L23,0) -> 0 | T23: =IFERROR(VLOOKUP(TRIM($A23),'Ações Finalizadas'!$A:$O,15,FALSE),"") | U23: =IFERROR(VLOOKUP(TRIM($A23),'Ações Não Finalizadas'!$A:$G,15,FALSE),"")
A24: Andressa Ibiapina | B24: andressa.ibiapina@to.sebrae.com.br | D24: Regional Norte | I24: Ativo | J24: Marcus Vinicius Vieira Queiroz | K24: Sim | L24: 10 | M24: 2025-11-24 | N24: 0 | O24: 0 | P24: 10 | Q24: 4 | R24: =IF(OR(L24="",L24=0)," ",IF(P24=L24,"Terminou","Não terminou")) -> Terminou | S24: =IFERROR(P24/L24,0) -> 1 | T24: =IFERROR(VLOOKUP(TRIM($A24),'Ações Finalizadas'!$A:$O,15,FALSE),"") -> Atendimento e Relacionamento com o Cliente, Gestão do Conhecimento e Documentação Institucional, Liderança e Gestão de Pessoas, Planejamento, Foco e Resultados, Vendas, Negociação e Soluções Comerciais, Comunicação | U24: =IFERROR(VLOOKUP(TRIM($A24),'Ações Não Finalizadas'!$A:$G,15,FALSE),"")
A25: Anteia Tavares | B25: anteia.tavares@to.sebrae.com.br | D25: UGOC-UNIDADE DE GESTÃO ORÇ. CONTABILIDADE E FINANÇAS | I25: Ativo | J25: Andreia Rodrigues Facundes | K25: Sim | L25: 2 | M25: 2025-09-09 | N25: 0 | O25: 0 | P25: 2 | Q25: 3 | R25: =IF(OR(L25="",L25=0)," ",IF(P25=L25,"Terminou","Não terminou")) -> Terminou | S25: =IFERROR(P25/L25,0) -> 1 | T25: =IFERROR(VLOOKUP(TRIM($A25),'Ações Finalizadas'!$A:$O,15,FALSE),"") -> Desenvolvimento Programa Integração | U25: =IFERROR(VLOOKUP(TRIM($A25),'Ações Não Finalizadas'!$A:$G,15,FALSE),"")
A26: Antonia Gelma Pereira da Silva Carvalho | B26: antonia.carvalho@to.sebrae.com.br | D26: Regional Metropolitana | I26: Ativo | J26: Amaggeldo Barbosa | K26: Sim | L26: 11 | M26: 2025-12-19 | N26: 3 | O26: 1 | P26: 7 | Q26: 4 | R26: =IF(OR(L26="",L26=0)," ",IF(P26=L26,"Terminou","Não terminou")) -> Não terminou | S26: =(P26 + O26*(1/3)) / L26 -> 0.66666667 | T26: =IFERROR(VLOOKUP(TRIM($A26),'Ações Finalizadas'!$A:$O,15,FALSE),"") -> Ética, Integridade e Responsabilidade, Políticas Públicas e Desenvolvimento Territorial, Vendas, Negociação e Soluções Comerciais, Comunicação | U26: =IFERROR(VLOOKUP(TRIM($A26),'Ações Não Finalizadas'!$A:$G,15,FALSE),"")
A27: Antonio Louça Curcino | B27: antonio.curcino@to.sebrae.com.br | D27: Regional Serras Gerais | I27: Ativo | J27: Antonio Louça Curcino | K27: Sim | L27: 7 | M27: 2025-12-12 | N27: 0 | O27: 0 | P27: 7 | Q27: 4 | R27: =IF(OR(L27="",L27=0)," ",IF(P27=L27,"Terminou","Não terminou")) -> Terminou | S27: =IFERROR(P27/L27,0) -> 1 | T27: =IFERROR(VLOOKUP(TRIM($A27),'Ações Finalizadas'!$A:$O,15,FALSE),"") -> Ética, Integridade e Responsabilidade, Gestão do Conhecimento e Documentação Institucional, Liderança e Gestão de Pessoas, Vendas, Negociação e Soluções Comerciais, Comunicação | U27: =IFERROR(VLOOKUP(TRIM($A27),'Ações Não Finalizadas'!$A:$G,15,FALSE),"")
A28: Antonio Luis Ferreira dos Anjos Filho | B28: antonio.filho@to.sebrae.com.br | D28: URC - UNIDADE DE RELACIONAMENTO COM O CLIENTE | I28: Ativo | J28: Emerson Montenegro Lima | K28: Sim | L28: 10 | M28: 2025-12-09 | N28: 0 | O28: 0 | P28: 10 | Q28: 4 | R28: =IF(OR(L28="",L28=0)," ",IF(P28=L28,"Terminou","Não terminou")) -> Terminou | S28: =IFERROR(P28/L28,0) -> 1 | T28: =IFERROR(VLOOKUP(TRIM($A28),'Ações Finalizadas'!$A:$O,15,FALSE),"") -> Atendimento e Relacionamento com o Cliente, Conhecimentos Práticos e Acadêmicos em Marketing, Ética, Integridade e Responsabilidade, Vendas, Negociação e Soluções Comerciais | U28: =IFERROR(VLOOKUP(TRIM($A28),'Ações Não Finalizadas'!$A:$G,15,FALSE),"")
A29: Antonio Neto dos Santos | B29: antonio.santos@to.sebrae.com.br | D29: UGE-UNIDADE DE GESTÃO ESTRATÉGICA E INTEGRIDADE | I29: Ativo | J29: Pedro Junior da Rocha Silva | K29: Sim | L29: 3 | M29: 2025-12-03 | N29: 3 | O29: 0 | P29: 0 | Q29: 2 | R29: =IF(OR(L29="",L29=0)," ",IF(P29=L29,"Terminou","Não terminou")) -> Não terminou | S29: =IFERROR(P29/L29,0) -> 0 | T29: =IFERROR(VLOOKUP(TRIM($A29),'Ações Finalizadas'!$A:$O,15,FALSE),"") | U29: =IFERROR(VLOOKUP(TRIM($A29),'Ações Não Finalizadas'!$A:$G,15,FALSE),"")
A30: Barbara de Moura Nunes Rezende | B30: barbara.nunes@to.sebrae.com.br | D30: URC - UNIDADE DE RELACIONAMENTO COM O CLIENTE | I30: Ativo | J30: Emerson Montenegro Lima | K30: Sim | L30: 2 | M30: 2025-11-19 | N30: 0 | O30: 0 | P30: 2 | Q30: 3 | R30: =IF(OR(L30="",L30=0)," ",IF(P30=L30,"Terminou","Não terminou")) -> Terminou | S30: =IFERROR(P30/L30,0) -> 1 | T30: =IFERROR(VLOOKUP(TRIM($A30),'Ações Finalizadas'!$A:$O,15,FALSE),"") -> Conhecimentos Práticos e Acadêmicos em Marketing | U30: =IFERROR(VLOOKUP(TRIM($A30),'Ações Não Finalizadas'!$A:$G,15,FALSE),"")
A31: Bruno de Jesus Rodrigues | B31: bruno.rodrigues@to.sebrae.com.br | D31: Regional Serras Gerais | I31: Ativo | J31: Antonio Louça Curcino | K31: Sim | L31: 7 | M31: 2025-12-16 | N31: 0 | O31: 0 | P31: 7 | Q31: 4 | R31: =IF(OR(L31="",L31=0)," ",IF(P31=L31,"Terminou","Não terminou")) -> Terminou | S31: =IFERROR(P31/L31,0) -> 1 | T31: =IFERROR(VLOOKUP(TRIM($A31),'Ações Finalizadas'!$A:$O,15,FALSE),"") -> Atitude Inovadora com Visão de Futuro, Gestão de Projetos e Processos, Inteligência Emocional e Autoconhecimento, Planejamento, Foco e Resultados, Presença Executiva, Estratégia e Indicadores, Comunicação | U31: =IFERROR(VLOOKUP(TRIM($A31),'Ações Não Finalizadas'!$A:$G,15,FALSE),"")
A32: Bruno Henrique Vila Verde | B32: bruno.vilaverde@to.sebrae.com.br | D32: UGE-UNIDADE DE GESTÃO ESTRATÉGICA E INTEGRIDADE | I32: Ativo | J32: Pedro Junior da Rocha Silva | K32: Sim | L32: 11 | M32: 2025-12-16 | N32: 0 | O32: 0 | P32: 11 | Q32: 4 | R32: =IF(OR(L32="",L32=0)," ",IF(P32=L32,"Terminou","Não terminou")) -> Terminou | S32: =IFERROR(P32/L32,0) -> 1 | T32: =IFERROR(VLOOKUP(TRIM($A32),'Ações Finalizadas'!$A:$O,15,FALSE),"") -> Atitude Inovadora com Visão de Futuro, Estratégia e Indicadores, Ética, Integridade e Responsabilidade, Gestão de Tempo, Inteligência Emocional e Autoconhecimento, Protagonismo, Autogestão e Tomada de Decisão, Resolução de Problemas, Comunicação | U32: =IFERROR(VLOOKUP(TRIM($A32),'Ações Não Finalizadas'!$A:$G,15,FALSE),"")
A33: Bruno Martins Vieira | B33: bruno.vieira@to.sebrae.com.br | D33: UAC-UNIDADE DE ARTICULAÇÃO E COMPETITIVIDADE | I33: Ativo | J33: Bruno Martins Vieira | K33: Sim | L33: 5 | M33: 2025-12-09 | N33: 0 | O33: 0 | P33: 5 | Q33: 4 | R33: =IF(OR(L33="",L33=0)," ",IF(P33=L33,"Terminou","Não terminou")) -> Terminou | S33: =IFERROR(P33/L33,0) -> 1 | T33: =IFERROR(VLOOKUP(TRIM($A33),'Ações Finalizadas'!$A:$O,15,FALSE),"") -> Atitude Inovadora com Visão de Futuro, Ética, Integridade e Responsabilidade, Gestão de Tempo, Tecnologia, Dados e Transformação Digital, Comunicação | U33: =IFERROR(VLOOKUP(TRIM($A33),'Ações Não Finalizadas'!$A:$G,15,FALSE),"")
A34: Carlucia Saraiva de Brito | B34: carlucia.brito@to.sebrae.com.br | D34: Regional Portal do Jalapao | I34: Ativo | J34: Millena Pereira Lima Rodrigues | K34: Sim | L34: 14 | M34: 2025-11-23 | N34: 0 | O34: 0 | P34: 14 | Q34: 4 | R34: =IF(OR(L34="",L34=0)," ",IF(P34=L34,"Terminou","Não terminou")) -> Terminou | S34: =IFERROR(P34/L34,0) -> 1 | T34: =IFERROR(VLOOKUP(TRIM($A34),'Ações Finalizadas'!$A:$O,15,FALSE),"") -> Ética, Integridade e Responsabilidade, Atendimento e Relacionamento com o Cliente, Estratégia e Indicadores, Gestão de Projetos e Processos, Gestão do Conhecimento e Documentação Institucional, Inteligência Emocional e Autoconhecimento, Liderança e Gestão de Pessoas, Planejamento, Foco e Resultados, Vendas, Negociação e Soluções Comerciais, Comunicação | U34: =IFERROR(VLOOKUP(TRIM($A34),'Ações Não Finalizadas'!$A:$G,15,FALSE),"")
A35: Celina Soares | B35: celina@to.sebrae.com.br | D35: UAC-UNIDADE DE ARTICULAÇÃO E COMPETITIVIDADE | I35: Ativo | J35: Bruno Martins Vieira | K35: Sim | L35: 2 | M35: 2025-10-06 | N35: 0 | O35: 0 | P35: 2 | Q35: 3 | R35: =IF(OR(L35="",L35=0)," ",IF(P35=L35,"Terminou","Não terminou")) -> Terminou | S35: =IFERROR(P35/L35,0) -> 1 | T35: =IFERROR(VLOOKUP(TRIM($A35),'Ações Finalizadas'!$A:$O,15,FALSE),"") -> Gestão de Projetos e Processos, Gestão de Tempo | U35: =IFERROR(VLOOKUP(TRIM($A35),'Ações Não Finalizadas'!$A:$G,15,FALSE),"")
A36: Cesar Augusto de Sa Moreira | B36: cesar.moreira@to.sebrae.com.br | D36: Regional Vale do Araguaia | I36: Ativo | J36: Renata Moura Alves Simas | K36: Sim | L36: 9 | M36: 2025-12-26 | N36: 1 | O36: 0 | P36: 8 | Q36: 4 | R36: =IF(OR(L36="",L36=0)," ",IF(P36=L36,"Terminou","Não terminou")) -> Não terminou | S36: =IFERROR(P36/L36,0) -> 0.88888889 | T36: =IFERROR(VLOOKUP(TRIM($A36),'Ações Finalizadas'!$A:$O,15,FALSE),"") -> Atendimento e Relacionamento com o Cliente, Compras, Facilities e Gestão Contratual, Ética, Integridade e Responsabilidade, Gestão de Projetos e Processos, Inteligência Emocional e Autoconhecimento, Tecnologia, Dados e Transformação Digital, Vendas, Negociação e Soluções Comerciais, Comunicação | U36: =IFERROR(VLOOKUP(TRIM($A36),'Ações Não Finalizadas'!$A:$G,15,FALSE),"")
A37: Clarice da Rosa Correa Soares | B37: clarice@to.sebrae.com.br | D37: Regional Metropolitana | I37: Ativo | J37: Amaggeldo Barbosa | K37: Sim | L37: 5 | M37: 2025-10-08 | N37: 0 | O37: 0 | P37: 5 | Q37: 4 | R37: =IF(OR(L37="",L37=0)," ",IF(P37=L37,"Terminou","Não terminou")) -> Terminou | S37: =IFERROR(P37/L37,0) -> 1 | T37: =IFERROR(VLOOKUP(TRIM($A37),'Ações Finalizadas'!$A:$O,15,FALSE),"") -> Ética, Integridade e Responsabilidade, Vendas, Negociação e Soluções Comerciais | U37: =IFERROR(VLOOKUP(TRIM($A37),'Ações Não Finalizadas'!$A:$G,15,FALSE),"")
A38: Claudete Pinto Carmo Sousa | B38: claudete.carmo@to.sebrae.com.br | D38: Regional Vale do Araguaia | I38: Ativo | J38: Renata Moura Alves Simas | K38: Sim | L38: 5 | M38: 2025-08-27 | N38: 5 | O38: 0 | P38: 0 | Q38: 2 | R38: =IF(OR(L38="",L38=0)," ",IF(P38=L38,"Terminou","Não terminou")) -> Não terminou | S38: =IFERROR(P38/L38,0) -> 0 | T38: =IFERROR(VLOOKUP(TRIM($A38),'Ações Finalizadas'!$A:$O,15,FALSE),"") | U38: =IFERROR(VLOOKUP(TRIM($A38),'Ações Não Finalizadas'!$A:$G,15,FALSE),"")
A39: Claudia Narciso Sakai | B39: claudia.sakai@to.sebrae.com.br | D39: UAC-UNIDADE DE ARTICULAÇÃO E COMPETITIVIDADE | I39: Ativo | J39: Bruno Martins Vieira | K39: Sim | L39: 5 | M39: 2025-08-28 | N39: 0 | O39: 0 | P39: 5 | Q39: 4 | R39: =IF(OR(L39="",L39=0)," ",IF(P39=L39,"Terminou","Não terminou")) -> Terminou | S39: =IFERROR(P39/L39,0) -> 1 | T39: =IFERROR(VLOOKUP(TRIM($A39),'Ações Finalizadas'!$A:$O,15,FALSE),"") -> Atitude Inovadora com Visão de Futuro, Ética, Integridade e Responsabilidade, Planejamento, Foco e Resultados, Presença Executiva, Protagonismo, Autogestão e Tomada de Decisão | U39: =IFERROR(VLOOKUP(TRIM($A39),'Ações Não Finalizadas'!$A:$G,15,FALSE),"")
A40: Cristyane Fonseca Cardoso | B40: cristyane.cardoso@to.sebrae.com.br | D40: Regional Serras Gerais | I40: Ativo | J40: Antonio Louça Curcino | K40: Sim | L40: 6 | M40: 2025-08-27 | N40: 0 | O40: 2 | P40: 4 | Q40: 4 | R40: =IF(OR(L40="",L40=0)," ",IF(P40=L40,"Terminou","Não terminou")) -> Não terminou | S40: =(P40 + O40*0.65) / L40 -> 0.88333333 | T40: =IFERROR(VLOOKUP(TRIM($A40),'Ações Finalizadas'!$A:$O,15,FALSE),"") -> Ética, Integridade e Responsabilidade, Gestão do Conhecimento e Documentação Institucional, Inteligência Emocional e Autoconhecimento, Comunicação, Desenvolvimento Programa Integração | U40: =IFERROR(VLOOKUP(TRIM($A40),'Ações Não Finalizadas'!$A:$G,15,FALSE),"")
...

Sheet Dinâmica % Finalizado por Time
A1: Contagem | B1: Rótulos de Coluna
A2: Áreas/Times | B2: Não terminou | C2: Terminou | D2: Total Geral | E2: PDIs TOTALMENTE Finalizados | F2: Média de Conclusão de Áreas por Time
A3: AUD-UNIDADE DE AUDITORIA INTERNA | C3: 2 | D3: 2 | E3: =IFERROR(C3/D3,0) -> 1 | F3: 1
A4: CDE-ASSESSORIA | C4: 3 | D4: 3 | E4: =IFERROR(C4/D4,0) -> 1 | F4: 1
A5: Regional Portal do Jalapao | B5: 2 | C5: 5 | D5: 7 | E5: =IFERROR(C5/D5,0) -> 0.71428571 | F5: 0.89455306
A6: Regional Bico do Papagaio | B6: 2 | C6: 4 | D6: 6 | E6: =IFERROR(C6/D6,0) -> 0.66666667 | F6: 0.98115079
A7: Regional Médio Norte Colinas | B7: 1 | C7: 7 | D7: 8 | E7: =IFERROR(C7/D7,0) -> 0.875 | F7: 0.99107143
A8: Regional Metropolitana | B8: 4 | C8: 10 | D8: 14 | E8: =IFERROR(C8/D8,0) -> 0.71428571 | F8: 0.9047619
A9: Regional Norte | C9: 8 | D9: 8 | E9: =IFERROR(C9/D9,0) -> 1 | F9: 1
A10: Regional Serras Gerais | B10: 4 | C10: 3 | D10: 7 | E10: =IFERROR(C10/D10,0) -> 0.42857143 | F10: 0.85113815
A11: Regional Sul | B11: 1 | C11: 7 | D11: 8 | E11: =IFERROR(C11/D11,0) -> 0.875 | F11: 0.93055556
A12: Regional Vale do Araguaia | B12: 6 | C12: 1 | D12: 7 | E12: =IFERROR(C12/D12,0) -> 0.14285714 | F12: 0.48888889
A13: SUPERINTENDENCIA | C13: 2 | D13: 2 | E13: =IFERROR(C13/D13,0) -> 1 | F13: 1
A14: UAC-UNIDADE DE ARTICULAÇÃO E COMPETITIVIDADE | C14: 9 | D14: 9 | E14: =IFERROR(C14/D14,0) -> 1 | F14: 1
A15: UAS-UNIDADE DE ADMINISTRAÇÃO E SUPRIMENTOS | C15: 10 | D15: 10 | E15: =IFERROR(C15/D15,0) -> 1 | F15: 1
A16: UGE-UNIDADE DE GESTÃO ESTRATÉGICA E INTEGRIDADE | B16: 1 | C16: 8 | D16: 9 | E16: =IFERROR(C16/D16,0) -> 0.88888889 | F16: 0.88888889
A17: UGOC-UNIDADE DE GESTÃO ORÇ. CONTABILIDADE E FINANÇAS | B17: 2 | C17: 12 | D17: 14 | E17: =IFERROR(C17/D17,0) -> 0.85714286 | F17: 0.9
A18: UGP-UNIDADE DE GESTÃO DE PESSOAS | B18: 3 | C18: 4 | D18: 7 | E18: =IFERROR(C18/D18,0) -> 0.57142857 | F18: 0.96123321
A19: UMC-UNIDADE DE MARKETING E COMUNICAÇÃO | C19: 8 | D19: 8 | E19: =IFERROR(C19/D19,0) -> 1 | F19: 1
A20: URC - UNIDADE DE RELACIONAMENTO COM O CLIENTE | B20: 1 | C20: 10 | D20: 11 | E20: =IFERROR(C20/D20,0) -> 0.90909091 | F20: 0.97272727
A21: URI-UNIDADE DE RELACIONAMENTO INSTITUCIONAL | C21: 8 | D21: 8 | E21: =IFERROR(C21/D21,0) -> 1 | F21: 1
A22: UTIC-UNIDADE DE TECNOLOGIA DA INFORM. E COMUNICAÇÃO DE DADOS | B22: 4 | C22: 4 | D22: 8 | E22: =IFERROR(C22/D22,0) -> 0.5 | F22: 0.703125
A23: Total Geral | B23: 31 | C23: 125 | D23: 156 | E23: =PDI!R158 -> 0.80128205 | F23: =AVERAGE(F3:F22) -> 0.92340471

Sheet Planilha4
A1: Time | B1: Total Pessoas | C1: Finalizaram | D1: % Finalizaram | E1: Média % Conclusão
A2: AUD-UNIDADE DE AUDITORIA INTERNA | B2: =COUNTIF(PDI!D:D,A2) -> 2 | C2: =COUNTIFS(PDI!D:D,A2,PDI!R:R,"Terminou") -> 2 | D2: =IFERROR(C2/B2,0) -> 1 | E2: =AVERAGEIF(PDI!D:D,A2,PDI!S:S) -> 1
A3: CDE-ASSESSORIA | B3: =COUNTIF(PDI!D:D,A3) -> 3 | C3: =COUNTIFS(PDI!D:D,A3,PDI!R:R,"Terminou") -> 3 | D3: =IFERROR(C3/B3,0) -> 1 | E3: =AVERAGEIF(PDI!D:D,A3,PDI!S:S) -> 1
A4: Regional Portal do Jalapao | B4: =COUNTIF(PDI!D:D,A4) -> 7 | C4: =COUNTIFS(PDI!D:D,A4,PDI!R:R,"Terminou") -> 5 | D4: =IFERROR(C4/B4,0) -> 0.71428571 | E4: =AVERAGEIF(PDI!D:D,A4,PDI!S:S) -> 0.89455306
A5: Regional Bico do Papagaio | B5: =COUNTIF(PDI!D:D,A5) -> 6 | C5: =COUNTIFS(PDI!D:D,A5,PDI!R:R,"Terminou") -> 4 | D5: =IFERROR(C5/B5,0) -> 0.66666667 | E5: =AVERAGEIF(PDI!D:D,A5,PDI!S:S) -> 0.98115079
A6: Regional Médio Norte Colinas | B6: =COUNTIF(PDI!D:D,A6) -> 8 | C6: =COUNTIFS(PDI!D:D,A6,PDI!R:R,"Terminou") -> 7 | D6: =IFERROR(C6/B6,0) -> 0.875 | E6: =AVERAGEIF(PDI!D:D,A6,PDI!S:S) -> 0.99107143
A7: Regional Metropolitana | B7: =COUNTIF(PDI!D:D,A7) -> 14 | C7: =COUNTIFS(PDI!D:D,A7,PDI!R:R,"Terminou") -> 10 | D7: =IFERROR(C7/B7,0) -> 0.71428571 | E7: =AVERAGEIF(PDI!D:D,A7,PDI!S:S) -> 0.9047619
A8: Regional Norte | B8: =COUNTIF(PDI!D:D,A8) -> 8 | C8: =COUNTIFS(PDI!D:D,A8,PDI!R:R,"Terminou") -> 8 | D8: =IFERROR(C8/B8,0) -> 1 | E8: =AVERAGEIF(PDI!D:D,A8,PDI!S:S) -> 1
A9: Regional Serras Gerais | B9: =COUNTIF(PDI!D:D,A9) -> 7 | C9: =COUNTIFS(PDI!D:D,A9,PDI!R:R,"Terminou") -> 3 | D9: =IFERROR(C9/B9,0) -> 0.42857143 | E9: =AVERAGEIF(PDI!D:D,A9,PDI!S:S) -> 0.85113815
A10: Regional Sul | B10: =COUNTIF(PDI!D:D,A10) -> 8 | C10: =COUNTIFS(PDI!D:D,A10,PDI!R:R,"Terminou") -> 7 | D10: =IFERROR(C10/B10,0) -> 0.875 | E10: =AVERAGEIF(PDI!D:D,A10,PDI!S:S) -> 0.93055556
A11: Regional Vale do Araguaia | B11: =COUNTIF(PDI!D:D,A11) -> 7 | C11: =COUNTIFS(PDI!D:D,A11,PDI!R:R,"Terminou") -> 1 | D11: =IFERROR(C11/B11,0) -> 0.14285714 | E11: =AVERAGEIF(PDI!D:D,A11,PDI!S:S) -> 0.48888889
A12: SUPERINTENDENCIA | B12: =COUNTIF(PDI!D:D,A12) -> 2 | C12: =COUNTIFS(PDI!D:D,A12,PDI!R:R,"Terminou") -> 2 | D12: =IFERROR(C12/B12,0) -> 1 | E12: =AVERAGEIF(PDI!D:D,A12,PDI!S:S) -> 1
A13: UAC-UNIDADE DE ARTICULAÇÃO E COMPETITIVIDADE | B13: =COUNTIF(PDI!D:D,A13) -> 9 | C13: =COUNTIFS(PDI!D:D,A13,PDI!R:R,"Terminou") -> 9 | D13: =IFERROR(C13/B13,0) -> 1 | E13: =AVERAGEIF(PDI!D:D,A13,PDI!S:S) -> 1
... A22: UTIC-UNIDADE DE TECNOLOGIA DA INFORM. E COMUNICAÇÃO DE DADOS | B22: =COUNTIF(PDI!D:D,A22) -> 8 | C22: =COUNTIFS(PDI!D:D,A22,PDI!R:R,"Terminou") -> 4 | D22: =IFERROR(C22/B22,0) -> 0.5 | E22: =AVERAGEIF(PDI!D:D,A22,PDI!S:S) -> 0.703125

Sheet Áreas de desenvolvimento
A1: Nome | B1: Email | C1: Cpf | D1: Times | E1: Tags Privadas | F1: Tags Públicas | G1: Área | H1: Identificador | I1: status | J1: Líder | K1: Área de desenvolvimento | L1: Descrição | M1: Categoria | N1: Criado em (yyyy-mm-dd) | O1: Atualizado em (yyyy-mm-dd) | P1: Progresso | Q1: Total de ações | R1: Finalizada
A2: Adelice Thomaz Soares Novak | B2: adelice@to.sebrae.com.br | D2: UAC-UNIDADE DE ARTICULAÇÃO E COMPETITIVIDADE | I2: Ativo | J2: Bruno Martins Vieira | K2: Macro Área do Comportamento: Liderança e Gestão de Pessoas | L2: Melhora a assertividade e análise na escolha de caminhos. | M2: Potencializar | N2: 2025-05-29 | O2: 2025-07-28 | P2: Finalizada | Q2: 1 | R2: 1
A3: Adelice Thomaz Soares Novak | B3: adelice@to.sebrae.com.br | D3: UAC-UNIDADE DE ARTICULAÇÃO E COMPETITIVIDADE | I3: Ativo | J3: Bruno Martins Vieira | K3: Macro Área do Comportamento: Ética, Integridade e Responsabilidade | L3: Fortalecer a conduta ética e o alinhamento aos princípios institucionais do Sebrae. | M3: Potencializar | N3: 2025-05-19 | O3: 2025-07-29 | P3: Finalizada | Q3: 1 | R3: 1
A4: Adelice Thomaz Soares Novak | B4: adelice@to.sebrae.com.br | D4: UAC-UNIDADE DE ARTICULAÇÃO E COMPETITIVIDADE | I4: Ativo | J4: Bruno Martins Vieira | K4: Macro Área do Comportamento: Comunicação e Relacionamento | L4: Fortalece a capacidade de expressar ideias com clareza, objetividade e respeito. | M4: Potencializar | N4: 2025-05-29 | O4: 2025-07-28 | P4: Finalizada | Q4: 1 | R4: 1
A5: Adelice Thomaz Soares Novak | B5: adelice@to.sebrae.com.br | D5: UAC-UNIDADE DE ARTICULAÇÃO E COMPETITIVIDADE | I5: Ativo | J5: Bruno Martins Vieira | K5: Macro Área do Comportamento: Planejamento, Foco e Resultados | L5: Desenvolve disciplina e visão de curto, médio e longo prazo. | M5: Potencializar | N5: 2025-05-29 | O5: 2025-08-14 | P5: Finalizada | Q5: 1 | R5: 1
A6: Adelice Thomaz Soares Novak | B6: adelice@to.sebrae.com.br | D6: UAC-UNIDADE DE ARTICULAÇÃO E COMPETITIVIDADE | I6: Ativo | J6: Bruno Martins Vieira | K6: Macro Área do Comportamento: Planejamento, Foco e Resultados | L6: Constrói reputação e direcionamento profissional estratégico. | M6: Potencializar | N6: 2025-05-29 | O6: 2025-07-29 | P6: Finalizada | Q6: 1 | R6: 1
A7: Adelice Thomaz Soares Novak | B7: adelice@to.sebrae.com.br | D7: UAC-UNIDADE DE ARTICULAÇÃO E COMPETITIVIDADE | I7: Ativo | J7: Bruno Martins Vieira | K7: Macro Área do Comportamento: Networking e Parcerias Estratégicas | L7: Expande oportunidades por meio de conexões relevantes. | M7: Potencializar | N7: 2025-05-29 | O7: 2025-08-19 | P7: Finalizada | Q7: 1 | R7: 1
A8: Adelice Thomaz Soares Novak | B8: adelice@to.sebrae.com.br | D8: UAC-UNIDADE DE ARTICULAÇÃO E COMPETITIVIDADE | I8: Ativo | J8: Bruno Martins Vieira | K8: Macro Área do Comportamento: Trabalho em Equipe e Colaboração | L8: Desenvolve a capacidade de atuar de forma eficaz, respeitosa e integrada com os colegas. | M8: Potencializar | N8: 2025-05-29 | O8: 2025-07-28 | P8: Finalizada | Q8: 2 | R8: 2
A9: Adelice Thomaz Soares Novak | B9: adelice@to.sebrae.com.br | D9: UAC-UNIDADE DE ARTICULAÇÃO E COMPETITIVIDADE | I9: Ativo | J9: Bruno Martins Vieira | K9: Macro Área Técnica: Tecnologia, Dados e Transformação Digital | L9: Promove aperfeiçoamento constante e adaptação a mudanças. | M9: Potencializar | N9: 2025-05-29 | O9: 2025-09-12 | P9: Finalizada | Q9: 1 | R9: 1
A10: Ademir Whitman Gomes Rego | B10: ademir@to.sebrae.com.br | D10: Regional Vale do Araguaia | I10: Ativo | J10: Renata Moura Alves Simas | K10: Macro Área do Comportamento: Comunicação e Relacionamento | L10: Aprimorar habilidades de comunicação clara e empática | M10: Potencializar | N10: 2025-04-17 | O10: 2025-07-25 | P10: Não iniciada | Q10: 1 | R10: 0
A11: Ademir Whitman Gomes Rego | B11: ademir@to.sebrae.com.br | D11: Regional Vale do Araguaia | I11: Ativo | J11: Renata Moura Alves Simas | K11: Macro Área Técnica: Tecnologia, Dados e Transformação Digital | L11: Inovação e soluções aplicáveis ao setor público | M11: Potencializar | N11: 2025-04-17 | O11: 2025-07-25 | P11: Não iniciada | Q11: 1 | R11: 0
A12: Ademir Whitman Gomes Rego | B12: ademir@to.sebrae.com.br | D12: Regional Vale do Araguaia | I12: Ativo | J12: Renata Moura Alves Simas | K12: Macro Área Técnica: Compras, Facilities e Gestão Contratual | L12: Gestão Pública Políticas públicas e desenvolvimento territorial Curso online | M12: Potencializar | N12: 2025-04-17 | O12: 2025-07-25 | P12: Não iniciada | Q12: 1 | R12: 0
A13: Ademir Whitman Gomes Rego | B13: ademir@to.sebrae.com.br | D13: Regional Vale do Araguaia | I13: Ativo | J13: Renata Moura Alves Simas | K13: Macro Área Técnica: Tecnologia, Dados e Transformação Digital | L13: Uso de Inteligência Artificial aplicada ao atendimento | M13: Potencializar | N13: 2025-04-17 | O13: 2025-07-25 | P13: Não iniciada | Q13: 1 | R13: 0
... A29: Admary Monteiro Barbosa | B29: admary.monteiro@to.sebrae.com.br | D29: Regional Portal do Jalapao | I29: Ativo | J29: Millena Pereira Lima Rodrigues | K29: Macro Área: Vendas, Negociação e Soluções Comerciais | L29: Negociação Institucional | M29: Potencializar | N29: 2025-03-31 | O29: 2025-12-19 | P29: Finalizada | Q29: 1 | R29: 1
A30: Adrielle Andrade | B30: adrielle.andrade@to.sebrae.com.br | D30: Regional Sul | I30: Ativo | J30: Paula dos Reis Coelho Alencar Sousa | K30: PDI - Onboarding (Competências Comportamentais) | M30: Potencializar | N30: 2025-11-07 | O30: 2025-12-19 | P30: Finalizada | Q30: 3 | R30: 3
A31: Adrielle Andrade | B31: adrielle.andrade@to.sebrae.com.br | D31: Regional Sul | I31: Ativo | J31: Paula dos Reis Coelho Alencar Sousa | K31: PDI - Onboarding (Tarefas da sua Gestão) | M31: Potencializar | N31: 2025-11-07 | O31: 2025-12-18 | P31: Finalizada | Q31: 4 | R31: 4
A32: Aldeni Batista Torres | B32: aldeni.torres@to.sebrae.com.br | D32: Regional Médio Norte Colinas | I32: Ativo | K32: Macro Área: Gestão de Projetos e Processos | L32: Competência Técnica: Gestão de Projetos e Processos Aprimoramento de conhecimentos específicos e ferramentas técnicas para otimizar a performance em funções estratégicas. | M32: Potencializar | N32: 2025-03-25 | O32: 2025-12-18 | P32: Finalizada | Q32: 1 | R32: 1
A33: Aldeni Batista Torres | B33: aldeni.torres@to.sebrae.com.br | D33: Regional Médio Norte Colinas | I33: Ativo | K33: Macro Área: Inteligência Emocional e Autoconhecimento | L33: Competência Comportamental: Desenvolvimento de Marca Pessoal Estratégias para fortalecimento da marca pessoal, planejamento profissional e ampliação de oportunidades de crescimento. | M33: Potencializar | N33: 2025-03-25 | O33: 2025-08-14 | P33: Finalizada | Q33: 1 | R33: 1
A34: Aldeni Batista Torres | B34: aldeni.torres@to.sebrae.com.br | D34: Regional Médio Norte Colinas | I34: Ativo | K34: Macro Área: Atendimento e Relacionamento com o Cliente | L34: Competência Comportamental: Networking e Parcerias Estratégicas | M34: Potencializar | N34: 2025-03-25 | O34: 2025-11-17 | P34: Finalizada | Q34: 1 | R34: 1
A35: Aldeni Batista Torres | B35: aldeni.torres@to.sebrae.com.br | D35: Regional Médio Norte Colinas | I35: Ativo | K35: Macro Área: Atendimento e Relacionamento com o Cliente | L35: Competência Comportamental: Negociação e Relacionamento com Clientes Capacidade de analisar cenários, tomar decisões e estabelecer conexões estratégicas para melhorar o impacto organizacional. | M35: Potencializar | N35: 2025-03-25 | O35: 2025-08-14 | P35: Não iniciada | Q35: 1 | R35: 0
A36: Aldeni Batista Torres | B36: aldeni.torres@to.sebrae.com.br | D36: Regional Médio Norte Colinas | I36: Ativo | K36: Macro Área: Gestão de Equipes | L36: Competência Comportamental: Liderança e Gestão de Equipes Aprimoramento da capacidade de influenciar, motivar e desenvolver equipes. Essencial para um ambiente organizacional produtivo. | M36: Potencializar | N36: 2025-03-25 | O36: 2025-12-02 | P36: Em progresso | Q36: 2 | R36: 1
A37: Aldeni Batista Torres | B37: aldeni.torres@to.sebrae.com.br | D37: Regional Médio Norte Colinas | I37: Ativo | K37: Macro Área: Protagonismo, Autogestão e Tomada de Decisão | L37: Competência Comportamental: Análise de Dados e Tomada de Decisão Capacidade de analisar cenários, tomar decisões e estabelecer conexões estratégicas para melhorar o impacto organizacional. | M37: Potencializar | N37: 2025-03-25 | O37: 2025-12-18 | P37: Finalizada | Q37: 1 | R37: 1
A38: Aldeni Batista Torres | B38: aldeni.torres@to.sebrae.com.br | D38: Regional Médio Norte Colinas | I38: Ativo | K38: Macro Área: Inteligência Emocional e Autoconhecimento | L38: Competência Comportamental: Desenvolvimento Pessoal e Inteligência Emocional Capacidade de se comunicar, interagir e colaborar com outras pessoas de forma eficaz. Ajuda a construir relacionamentos, resolver conflitos e fortalecer a influência. | M38: Potencializar | N38: 2025-03-25 | O38: 2025-08-14 | P38: Finalizada | Q38: 1 | R38: 1
A39: Alencar Hubner Borelli | B39: alencar.borelli@to.sebrae.com.br | D39: UAS-UNIDADE DE ADMINISTRAÇÃO E SUPRIMENTOS | I39: Ativo | J39: Ana Paula Alves Santos | K39: Macro Área: Ética, Integridade e Responsabilidade | L39: Competência Técnica: Ética e Conformidade Fortalecer a conduta ética e o alinhamento aos princípios institucionais do Sebrae. | M39: Potencializar | N39: 2025-05-19 | O39: 2025-12-01 | P39: Finalizada | Q39: 1 | R39: 1
A40: Alencar Hubner Borelli | B40: alencar.borelli@to.sebrae.com.br | D40: UAS-UNIDADE DE ADMINISTRAÇÃO E SUPRIMENTOS | I40: Ativo | J40: Ana Paula Alves Santos | K40: Macro Área: Desenvolvimento de Ferramentas de Apoio na Execução | L40: Competência Técnica: Ferramentas Digitais para Facilities e Compras Desenvolver habilidades práticas e conhecimentos avançados sobre ferramentas digitais que podem otimizar o gerenciamento de facilities e compras, trazendo mais agilidade e controle. | M40: Potencializar | N40: 2025-06-03 | O40: 2025-12-04 | P40: Finalizada | Q40: 1 | R40: 1
A41: Alex Veras Dias | B41: alex.dias@to.sebrae.com.br | D41: URI-UNIDADE DE RELACIONAMENTO INSTITUCIONAL | I41: Ativo | J41: Gilzane Pereira Amaral | K41: Macro Área: Políticas Públicas e Desenvolvimento Territorial | L41: Competência Técnica: Desenvolvimento Territorial e Economia Regional Ampliar o conhecimento sobre as dinâmicas do desenvolvimento territorial e da economia regional, com foco específico na realidade do Tocantins, para embasar estratégias e articulações. (Fonte: Questionário - Temas, Cargo) | M41: Potencializar | N41: 2025-05-29 | O41: 2025-11-27 | P41: Finalizada | Q41: 1 | R41: 1
A42: Alex Veras Dias | B42: alex.dias@to.sebrae.com.br | D42: URI-UNIDADE DE RELACIONAMENTO INSTITUCIONAL | I42: Ativo | J42: Gilzane Pereira Amaral | K42: Macro Área: Planejamento, Foco e Resultados | L42: Competência Comportamental: Gestão da Ansiedade e Foco Desenvolver estratégias para gerenciar a ansiedade e a inquietude, melhorando o foco e a tranquilidade na execução das tarefas e tomada de decisão. (Fonte: PDI Anterior - Fraquezas, DISC) | M42: Potencializar | N42: 2025-05-29 | O42: 2025-11-27 | P42: Finalizada | Q42: 1 | R42: 1
A43: Alex Veras Dias | B43: alex.dias@to.sebrae.com.br | D43: URI-UNIDADE DE RELACIONAMENTO INSTITUCIONAL | I43: Ativo | J43: Gilzane Pereira Amaral | K43: Macro Área: Gestão de Tempo | L43: Competência Técnica: Gestão do Tempo e Priorização de Demandas Otimizar a gestão do tempo e a capacidade de priorização para lidar com o volume de demandas de forma eficaz, garantindo a entrega de resultados estratégicos. (Fonte: Questionário - Desafios) | M43: Potencializar | N43: 2025-05-29 | O43: 2025-12-19 | P43: Finalizada | Q43: 1 | R43: 1
A44: Alex Veras Dias | B44: alex.dias@to.sebrae.com.br | D44: URI-UNIDADE DE RELACIONAMENTO INSTITUCIONAL | I44: Ativo | J44: Gilzane Pereira Amaral | K44: Macro Área: Visão Sistêmica com foco em Indicadores Estratégicos | L44: Competência Técnica: Liderança Estratégica e Visão Sistêmica Fortalecer a capacidade de pensar e agir estrategicamente, desenvolvendo uma visão sistêmica do negócio e do território para liderar iniciativas de maior impacto. (Fonte: Questionário - Competências, Avaliação - C, DISC - Talento Facilitador/Articulador) | M44: Potencializar | N44: 2025-05-29 | O44: 2025-12-16 | P44: Finalizada | Q44: 1 | R44: 1
A45: Alex Veras Dias | B45: alex.dias@to.sebrae.com.br | D45: URI-UNIDADE DE RELACIONAMENTO INSTITUCIONAL | I45: Ativo | J45: Gilzane Pereira Amaral | K45: Macro Área: Ética, Integridade e Responsabilidade | L45: Competência Técnica: Ética e Conformidade Fortalecer a conduta ética e o alinhamento aos princípios institucionais do Sebrae. | M45: Potencializar | N45: 2025-05-19 | O45: 2025-08-27 | P45: Finalizada | Q45: 1 | R45: 1
A46: Alex Veras Dias | B46: alex.dias@to.sebrae.com.br | D46: URI-UNIDADE DE RELACIONAMENTO INSTITUCIONAL | I46: Ativo | J46: Gilzane Pereira Amaral | K46: Macro Área: Comunicação Estratégica e Influente | L46: Competência Comportamental: Comunicação Eficaz e Feedback Construtivo Aprimorar a clareza, a escuta ativa e a assertividade na comunicação interpessoal e ao fornecer/receber feedback, visando interações mais fluidas e construtivas. (Fonte: Questionário, Avaliação de Competências - B, PDI Anterior, DISC) | M46: Potencializar | N46: 2025-05-29 | O46: 2025-10-30 | P46: Finalizada | Q46: 1 | R46: 1
A47: Alex Veras Dias | B47: alex.dias@to.sebrae.com.br | D47: URI-UNIDADE DE RELACIONAMENTO INSTITUCIONAL | I47: Ativo | J47: Gilzane Pereira Amaral | K47: Macro Área: Finanças, Orçamento e Contabilidade Pública | L47: Competência Técnica:: Gestão de Convênios para colaboradores do Sistema Sebrae O curso Gestão de Convênios para colaboradores do Sistema Sebrae foi projetado para fornecer a você as ferramentas e o conhecimento necessários para navegar com segurança e eficiência pelos processos, diretrizes e práticas de gestão de convênios. | M47: Potencializar | N47: 2025-06-10 | O47: 2025-10-30 | P47: Finalizada | Q47: 1 | R47: 1
A48: Alex Veras Dias | B48: alex.dias@to.sebrae.com.br | D48: URI-UNIDADE DE RELACIONAMENTO INSTITUCIONAL | I48: Ativo | J48: Gilzane Pereira Amaral | K48: Macro Área: Estratégia focada em Indicadores | L48: Competência Técnica: Análise e Formulação de Políticas Públicas para Pequenos Negócios Aprofundar o conhecimento técnico sobre o ciclo de políticas públicas, metodologias de análise e formulação, com foco nas necessidades dos pequenos negócios. (Fonte: Questionário - Temas, Cargo) | M48: Potencializar | N48: 2025-05-29 | O48: 2025-11-27 | P48: Finalizada | Q48: 1 | R48: 1
A49: Alex Veras Dias | B49: alex.dias@to.sebrae.com.br | D49: URI-UNIDADE DE RELACIONAMENTO INSTITUCIONAL | I49: Ativo | J49: Gilzane Pereira Amaral | K49: Macro Área: Liderança e Gestão de Pessoas | L49: Competência Comportamental: Delegação Eficaz e Gestão da Centralização- Desenvolver a habilidade de delegar tarefas de forma clara e confiante, superando a tendência à centralização, para otimizar o tempo e potencializar a equipe. (Fonte: PDI Anterior - Fraquezas) | M49: Potencializar | N49: 2025-05-29 | O49: 2025-12-19 | P49: Finalizada | Q49: 1 | R49: 1
A50: Alice Sousa Santos Costa | B50: alice.costa@to.sebrae.com.br | D50: Regional Sul | I50: Ativo | J50: Paula dos Reis Coelho Alencar Sousa | K50: Macro Área: Comunicação e Relacionamento | L50: Competência Comportamental: Empatia & Relacionamento Interpessoal Sensibilidade para lidar com diferentes perfis. | M50: Potencializar | N50: 2025-03-28 | O50: 2025-09-03 | P50: Finalizada | Q50: 2 | R50: 2
... A56: Alice Sousa Santos Costa | B56: alice.costa@to.sebrae.com.br | D56: Regional Sul | I56: Ativo | J56: Paula dos Reis Coelho Alencar Sousa | K56: Macro Área: Gestão do Conhecimento e Documentação Institucional | L56: Competência Técnica: Conhecimento Técnico Domínio sobre o portfólio Sebrae e adaptação ao público | M56: Potencializar | N56: 2025-03-28 | O56: 2025-12-01 | P56: Finalizada | Q56: 3 | R56: 3
A57: Aline Almeida | B57: aline.almeida@to.sebrae.com.br | D57: Regional Médio Norte Colinas | I57: Ativo | J57: Aldeni Batista Torres | K57: PDI - Onboarding (Competências Comportamentais) | M57: Potencializar | N57: 2025-10-03 | O57: 2025-12-15 | P57: Finalizada | Q57: 10 | R57: 10
A58: Aline Almeida | B58: aline.almeida@to.sebrae.com.br | D58: Regional Médio Norte Colinas | I58: Ativo | J58: Aldeni Batista Torres | K58: PDI - Onboarding (Tarefas da sua Gestão) | M58: Potencializar | N58: 2025-10-03 | O58: 2025-12-08 | P58: Finalizada | Q58: 3 | R58: 3
A59: Alorran de Freitas Barbosa | B59: alorran.barbosa@to.sebrae.com.br | D59: UTIC-UNIDADE DE TECNOLOGIA DA INFORM. E COMUNICAÇÃO DE DADOS | I59: Ativo | J59: Leonardo Campelo Leite Guedes | K59: Macro Área: Ética, Integridade e Responsabilidade | L59: Competência Técnica: Ética e Conformidade Fortalecer a conduta ética e o alinhamento aos princípios institucionais do Sebrae. | M59: Potencializar | N59: 2025-05-19 | O59: 2025-08-27 | P59: Não iniciada | Q59: 1 | R59: 0
A60: Alorran de Freitas Barbosa | B60: alorran.barbosa@to.sebrae.com.br | D60: UTIC-UNIDADE DE TECNOLOGIA DA INFORM. E COMUNICAÇÃO DE DADOS | I60: Ativo | J60: Leonardo Campelo Leite Guedes | K60: Macro Área: Tecnologia, Dados e Transformação Digital | L60: Competência Técnica: Análise de Dados e Visualização com Power BI Desenvolver capacidade de transformar dados em informações visuais e estratégicas por meio de ferramentas como Power BI. | M60: Potencializar | N60: 2025-05-12 | O60: 2025-08-19 | P60: Não iniciada | Q60: 1 | R60: 0
...

Sheet Ações Finalizadas
A1: Nome | B1: Email | C1: Times | D1: status | E1: Líder | F1: Área de desenvolvimento | G1: Padronização | H1: Descrição | I1: Categoria | J1: Ação | K1: Descrição | L1: Categoria | M1: Data de entrega (yyyy-mm-dd) | N1: Concluído em (yyyy-mm-dd) | O1: Todas as MacroÁreas
A2: Ana Maria Leal Cunha de Freitas | B2: ana.freitas@to.sebrae.com.br | C2: Regional Médio Norte Colinas | D2: Ativo | E2: Aldeni Batista Torres | F2: Macro Área: Ética, Integridade e Responsabilidade | G2: Macro Área: Ética, Integridade e Responsabilidade | H2: Competência Técnica: Ética e Conformidade Fortalecer a conduta ética e o alinhamento aos princípios institucionais do Sebrae. | I2: Potencializar | J2: AÇÃO: Concluir o Programa de Integridade – UC Sebrae | K2: SEGUE A AÇÃO: A ação foi indicada para o seu desenvolvimento e que entendemos podem lhe ajudar neste desafio de aprimorar suas competências. Caso deseje propor outra ação diferente desta opção, converse com sua liderança e registre a opção alternativa nos comentários para que possamos incluí-la no seu plano. Não há necessidade de apagar a que já consta — qualquer uma que concluir será considerada como AÇÃO REALIZADA. AÇÃO – Concluir o curso “Programa de Integridade” do Sistema Sebrae JUSTIFICATIVA: Esta ação integra o Programa de Integridade do Sistema Sebrae e é essencial para o fortalecimento da cultura organizacional baseada em ética e responsabilidade. A realização do curso é obrigatória para todos os colaboradores, garantindo alinhamento às diretrizes institucionais e promovendo práticas transparentes e responsáveis no ambiente de trabalho. COMO REALIZAR A AÇÃO: Acesse a Plataforma UC Sebrae. Pesquise pelo curso “Programa de Integridade”. Conclua todos os módulos obrigatórios. Reflita sobre os conteúdos apresentados e registre suas percepções quanto à aplicação prática no dia a dia profissional. ONDE FAZER: Plataforma UC Sebrae (pesquisar por: Programa de Integridade) Estas são apenas sugestões — a escolha deve ser alinhada com sua liderança. MATERIAL DE APOIO: Curso completo: Programa de Integridade – UC Sebrae Materiais complementares disponíveis na plataforma Documentos institucionais sobre ética, conduta profissional e integridade Pesquise por materiais ou cursos adicionais que reforcem a compreensão sobre compliance e cultura ética, preferencialmente na Universidade Sebrae e Degreed COMO COMPROVAR: Certificado de conclusão emitido pela Plataforma UC Sebrae Validação da liderança, se necessário, conforme os procedimentos internos | L2: Treinamento e estudo | M2: 2025-09-18 | N2: 2025-08-28 | O2: Ética, Integridade e Responsabilidade, Atitude Inovadora com Visão de Futuro, Finanças, Orçamento e Contabilidade Pública, Gestão de Projetos e Processos, Gestão de Tempo, Protagonismo, Autogestão e Tomada de Decisão, Vendas, Negociação e Soluções Comerciais, Competências Técnicas da Área, Comunicação, Desenvolvimento Programa Integração
A3: Clarice da Rosa Correa Soares | B3: clarice@to.sebrae.com.br | C3: Regional Metropolitana | D3: Ativo | E3: Amaggeldo Barbosa | F3: Macro Área: Ética, Integridade e Responsabilidade | G3: Macro Área: Ética, Integridade e Responsabilidade | H3: Competência Técnica: Ética e Conformidade Fortalecer a conduta ética e o alinhamento aos princípios institucionais do Sebrae. | I3: Potencializar | J3: Concluir o Programa de Integridade – UC Sebrae | K3: JUSTIFICATIVA: Esta ação faz parte do Programa de Integridade do Sistema Sebrae e é fundamental para o fortalecimento da cultura organizacional baseada em ética e responsabilidade . A realização do curso é obrigatória para todos os colaboradores . COMO REALIZAR A AÇÃO: Acesse a Plataforma UC Sebrae , localize o curso “Programa de Integridade” e conclua todos os módulos obrigatórios . Durante o curso, reflita sobre os conteúdos e registre suas percepções . ONDE FAZER: Plataforma UC Sebrae COMO COMPROVAR: Certificado de conclusão ou captura da tela com o curso finalizado (print) . | L3: Treinamento e estudo | M3: 2025-05-20 | N3: 2025-10-08 | O3: Ética, Integridade e Responsabilidade, Vendas, Negociação e Soluções Comerciais
A4: Eligeneth Resplandes Pimentel Gomes | B4: eligeneth@to.sebrae.com.br | C4: Regional Metropolitana | D4: Ativo | E4: Amaggeldo Barbosa | F4: Macro Área: Ética, Integridade e Responsabilidade | G4: Macro Área: Ética, Integridade e Responsabilidade | H4: Competência Técnica: Ética e Conformidade Fortalecer a conduta ética e o alinhamento aos princípios institucionais do Sebrae. | I4: Potencializar | J4: Concluir o Programa de Integridade – UC Sebrae | K4: Título da Ação: Curso "Programa de Integridade" – UC Sebrae Justificativa: Esta ação integra o Programa de Integridade do Sistema Sebrae e é essencial para o fortalecimento da cultura organizacional baseada em ética e responsabilidade. É exigida a realização do curso por todos os colaboradores . Como Realizar a Ação: Acesse a Plataforma UC Sebrae , localize o curso "Programa de Integridade" e conclua todos os módulos obrigatórios. Reflita sobre os conteúdos e registre suas percepções. Onde Fazer: Plataforma UC Sebrae (pesquisar por: Programa de Integridade ). Como Comprovar: Certificado de conclusão emitido pela plataforma. | L4: Treinamento e estudo | M4: 2025-12-15 | N4: 2025-08-15 | O4: Ética, Integridade e Responsabilidade, Inteligência Emocional e Autoconhecimento, Planejamento, Foco e Resultados, Vendas, Negociação e Soluções Comerciais, Comunicação
A5: Raquel Montelo Moura Carvalho | B5: raquel.carvalho@to.sebrae.com.br | C5: URC - UNIDADE DE RELACIONAMENTO COM O CLIENTE | D5: Ativo | E5: Emerson Montenegro Lima | F5: Macro Área: Ética, Integridade e Responsabilidade | G5: Macro Área: Ética, Integridade e Responsabilidade | H5: Competência Técnica: Ética e Conformidade Fortalecer a conduta ética e o alinhamento aos princípios institucionais do Sebrae. | I5: Potencializar | J5: Concluir o Programa de Integridade – UC Sebrae | K5: JUSTIFICATIVA: Esta ação integra o Programa de Integridade do Sistema Sebrae e é essencial para o fortalecimento da cultura organizacional baseada em ética e responsabilidade. É exigida a realização do curso por todos os colaboradores. COMO REALIZAR A AÇÃO: Acesse a Plataforma UC Sebrae, localize o curso "Programa de Integridade" e conclua todos os módulos obrigatórios. Reflita sobre os conteúdos e registre suas percepções. ONDE FAZER: Plataforma UC Sebrae (pesquisar por: Programa de Integridade) COMO COMPROVAR: Certificado de conclusão emitido pela plataforma. | L5: Treinamento e estudo | M5: 2025-12-02 | N5: 2025-12-03 | O5: Ética, Integridade e Responsabilidade, Atendimento e Relacionamento com o Cliente, Atitude Inovadora com Visão de Futuro, Conhecimentos Práticos e Acadêmicos em Marketing, Gestão de Tempo
A6: Deilane Rodrigues Vieira | B6: deilane.vieira@to.sebrae.com.br | C6: Regional Norte | D6: Ativo | E6: Marcus Vinicius Vieira Queiroz | F6: Macro Área: Ética, Integridade e Responsabilidade | G6: Macro Área: Ética, Integridade e Responsabilidade | H6: Competência Técnica: Ética e Conformidade Fortalecer a conduta ética e o alinhamento aos princípios institucionais do Sebrae. | I6: Potencializar | J6: Concluir o Programa de Integridade – UC Sebrae | K6: JUSTIFICATIVA Esta ação integra o Programa de Integridade do Sistema Sebrae e é essencial para o fortalecimento de uma cultura organizacional pautada na ética, transparência e responsabilidade . A realização do curso é obrigatória para todos os colaboradores , contribuindo para o alinhamento institucional e a consolidação de práticas éticas no dia a dia. COMO REALIZAR A AÇÃO Acesse a Plataforma UC Sebrae ; Localize o curso "Programa de Integridade" por meio da busca; Conclua todos os módulos obrigatórios do curso; Reflita sobre os conteúdos abordados e registre suas percepções , conforme orientações internas (se aplicável). ONDE FAZER Na Plataforma UC Sebrae (pesquisar por: Programa de Integridade ). COMO COMPROVAR Certificado de conclusão emitido diretamente pela plataforma após a finalização do curso. | L6: Treinamento e estudo | M6: 2025-07-31 | N6: 2025-07-07 | O6: Ética, Integridade e Responsabilidade, Atitude Inovadora com Visão de Futuro, Gestão do Conhecimento e Documentação Institucional, Inteligência Emocional e Autoconhecimento, Liderança e Gestão de Pessoas, Planejamento, Foco e Resultados, Vendas, Negociação e Soluções Comerciais, Comunicação
A7: Emerson Montenegro Lima | B7: emerson.lima@to.sebrae.com.br | C7: URC - UNIDADE DE RELACIONAMENTO COM O CLIENTE | D7: Ativo | F7: Macro Área: Ética, Integridade e Responsabilidade | G7: Macro Área: Ética, Integridade e Responsabilidade | H7: Competência Técnica: Ética e Conformidade Fortalecer a conduta ética e o alinhamento aos princípios institucionais do Sebrae. | I7: Potencializar | J7: Concluir o Programa de Integridade – UC Sebrae | K7: Concluir curso Código de Ética JUSTIFICATIVA: Esta ação visa garantir que todos os colaboradores estejam em conformidade com as diretrizes éticas institucionais do Sistema Sebrae, conforme exigência do Programa de Integridade. O curso é obrigatório para todos os empregados ativos. COMO REALIZAR A AÇÃO: Acesse a Plataforma UC Sebrae. Pesquise e localize o curso "Código de Ética 2024". Reserve um tempo para leitura atenta do conteúdo. Reflita sobre a aplicação prática das diretrizes apresentadas. Conclua todas as etapas do curso. ONDE FAZER: Plataforma UC Sebrae (pesquisar por: Código de Ética 2024). Estas são apenas sugestões — a escolha deve ser alinhada com sua liderança e validada pela UGP. MATERIAL DE APOIO: Curso "Código de Ética 2024" disponível na Plataforma UC Sebrae Materiais institucionais do Programa de Integridade, se disponíveis COMO COMPROVAR: Certificado de conclusão emitido pela plataforma. | L7: Treinamento e estudo | M7: 2025-07-15 | N7: 2025-07-16 | O7: Ética, Integridade e Responsabilidade, Atitude Inovadora com Visão de Futuro, Gestão de Tempo, Planejamento, Foco e Resultados, Presença Executiva, Protagonismo, Autogestão e Tomada de Decisão, Resolução de Problemas, Tecnologia, Dados e Transformação Digital, Estratégia e Indicadores, Comunicação
